<?xml version="1.0" encoding="utf-8"?>
<!-- This URDF was automatically created by SolidWorks to URDF Exporter! Originally created by Stephen Brawner (brawner@gmail.com) 
     Commit Version: 1.6.0-4-g7f85cfe  Build Version: 1.6.7995.38578
     For more information, please see http://wiki.ros.org/sw_urdf_exporter -->
<robot
  name="robot1">
  <link
    name="base_link">
    <inertial>
      <origin
        xyz="-5.78342767377806E-17 3.20113853670739E-17 0.06"
        rpy="0 0 0" />
      <mass
        value="21.6942477796077" />
      <inertia
        ixx="0.191279933343014"
        ixy="7.43271411215649E-17"
        ixz="-2.98049293693505E-18"
        iyy="0.677694623573289"
        iyz="3.1128339403067E-35"
        izz="0.817129844527322" />
    </inertial>
    <visual>
      <origin
        xyz="0 0 0"
        rpy="0 0 0" />
      <geometry>
        <mesh
          filename="package://robot1/meshes/base_link.STL" />
      </geometry>
      <material
        name="">
        <color
          rgba="0.792156862745098 0.819607843137255 0.933333333333333 1" />
      </material>
    </visual>
    <collision>
      <origin
        xyz="0 0 0"
        rpy="0 0 0" />
      <geometry>
        <mesh
          filename="package://robot1/meshes/base_link.STL" />
      </geometry>
    </collision>
  </link>
  <link
    name="front_left_wheel">
    <inertial>
      <origin
        xyz="0.200000000000035 0.194999999998909 0.0600000000000475"
        rpy="0 0 0" />
      <mass
        value="2.11669573162386" />
      <inertia
        ixx="0.00765610745123127"
        ixy="-8.66966066338475E-16"
        ixz="1.20324171323343E-13"
        iyy="0.0140448819805897"
        iyz="-2.71646475761896E-15"
        izz="0.00765610745142051" />
    </inertial>
    <visual>
      <origin
        xyz="0 0 0"
        rpy="0 0 0" />
      <geometry>
        <mesh
          filename="package://robot1/meshes/front_left_wheel.STL" />
      </geometry>
      <material
        name="">
        <color
          rgba="0.898039215686275 0.898039215686275 0.898039215686275 1" />
      </material>
    </visual>
    <collision>
      <origin
        xyz="0 0 0"
        rpy="0 0 0" />
      <geometry>
        <mesh
          filename="package://robot1/meshes/front_left_wheel.STL" />
      </geometry>
    </collision>
  </link>
  <joint
    name="front_left_joint"
    type="continuous">
    <origin
      xyz="0 0 0"
      rpy="0 0 0" />
    <parent
      link="base_link" />
    <child
      link="front_left_wheel" />
    <axis
      xyz="0 1 0" />
  </joint>
  <link
    name="front_right_wheel">
    <inertial>
      <origin
        xyz="0.200000000000023 -0.194999999998911 0.0599999999999489"
        rpy="0 0 0" />
      <mass
        value="2.11669573162387" />
      <inertia
        ixx="0.00765610745119546"
        ixy="2.49845748499387E-16"
        ixz="-8.03577728719601E-14"
        iyy="0.0140448819805898"
        iyz="-2.46054607369482E-15"
        izz="0.00765610745145606" />
    </inertial>
    <visual>
      <origin
        xyz="0 0 0"
        rpy="0 0 0" />
      <geometry>
        <mesh
          filename="package://robot1/meshes/front_right_wheel.STL" />
      </geometry>
      <material
        name="">
        <color
          rgba="0.898039215686275 0.898039215686275 0.898039215686275 1" />
      </material>
    </visual>
    <collision>
      <origin
        xyz="0 0 0"
        rpy="0 0 0" />
      <geometry>
        <mesh
          filename="package://robot1/meshes/front_right_wheel.STL" />
      </geometry>
    </collision>
  </link>
  <joint
    name="front_right_joint"
    type="continuous">
    <origin
      xyz="0 0 0"
      rpy="0 0 0" />
    <parent
      link="base_link" />
    <child
      link="front_right_wheel" />
    <axis
      xyz="0 -1 0" />
  </joint>
  <link
    name="rear_left_wheel">
    <inertial>
      <origin
        xyz="-0.200000000000055 0.194999999998913 0.0599999999999808"
        rpy="0 0 0" />
      <mass
        value="2.11669573162387" />
      <inertia
        ixx="0.00765610745141972"
        ixy="1.7353923965969E-15"
        ixz="1.20717980562506E-13"
        iyy="0.0140448819805897"
        iyz="1.22107409560405E-15"
        izz="0.0076561074512315" />
    </inertial>
    <visual>
      <origin
        xyz="0 0 0"
        rpy="0 0 0" />
      <geometry>
        <mesh
          filename="package://robot1/meshes/rear_left_wheel.STL" />
      </geometry>
      <material
        name="">
        <color
          rgba="0.898039215686275 0.898039215686275 0.898039215686275 1" />
      </material>
    </visual>
    <collision>
      <origin
        xyz="0 0 0"
        rpy="0 0 0" />
      <geometry>
        <mesh
          filename="package://robot1/meshes/rear_left_wheel.STL" />
      </geometry>
    </collision>
  </link>
  <joint
    name="rear_left_joint"
    type="continuous">
    <origin
      xyz="0 0 0"
      rpy="0 0 0" />
    <parent
      link="base_link" />
    <child
      link="rear_left_wheel" />
    <axis
      xyz="0 1 0" />
  </joint>
  <link
    name="rear_right_wheel">
    <inertial>
      <origin
        xyz="-0.200000000000007 -0.194999999998909 0.0600000000000545"
        rpy="0 0 0" />
      <mass
        value="2.11669573162388" />
      <inertia
        ixx="0.0076561074511742"
        ixy="7.12118175588418E-16"
        ixz="1.9997330725558E-14"
        iyy="0.0140448819805899"
        iyz="2.84765902463033E-15"
        izz="0.00765610745147777" />
    </inertial>
    <visual>
      <origin
        xyz="0 0 0"
        rpy="0 0 0" />
      <geometry>
        <mesh
          filename="package://robot1/meshes/rear_right_wheel.STL" />
      </geometry>
      <material
        name="">
        <color
          rgba="0.898039215686275 0.898039215686275 0.898039215686275 1" />
      </material>
    </visual>
    <collision>
      <origin
        xyz="0 0 0"
        rpy="0 0 0" />
      <geometry>
        <mesh
          filename="package://robot1/meshes/rear_right_wheel.STL" />
      </geometry>
    </collision>
  </link>
  <joint
    name="rear_right_joint"
    type="continuous">
    <origin
      xyz="0 0 0"
      rpy="0 0 0" />
    <parent
      link="base_link" />
    <child
      link="rear_right_wheel" />
    <axis
      xyz="0 -1 0" />
    <limit
      effort="30"
      velocity="30" />
  </joint>
</robot>