<?xml version="1.0" encoding="utf-8"?>
<!-- This URDF was automatically created by SolidWorks to URDF Exporter! Originally created by Stephen Brawner (brawner@gmail.com) 
     Commit Version: 1.6.0-4-g7f85cfe  Build Version: 1.6.7995.38578
     For more information, please see http://wiki.ros.org/sw_urdf_exporter -->
<robot
  name="pip">
  <link
    name="base_link">
    <inertial>
      <origin
        xyz="-8.1243457881439E-18 4.57903182795049E-17 0.03"
        rpy="0 0 0" />
      <mass
        value="23.8752202305694" />
      <inertia
        ixx="0.449048689155945"
        ixy="-2.35758916904458E-18"
        ixz="-1.57164907896417E-18"
        iyy="1.32622550789332"
        iyz="-3.45471987244402E-18"
        izz="1.76100090118971" />
    </inertial>
    <visual>
      <origin
        xyz="0 0 0"
        rpy="0 0 0" />
      <geometry>
        <mesh
          filename="package://pip/meshes/base_link.STL" />
      </geometry>
      <material
        name="">
        <color
          rgba="0.792156862745098 0.819607843137255 0.933333333333333 1" />
      </material>
    </visual>
    <collision>
      <origin
        xyz="0 0 0"
        rpy="0 0 0" />
      <geometry>
        <mesh
          filename="package://pip/meshes/base_link.STL" />
      </geometry>
    </collision>
  </link>
  <link
    name="front_left_wheel">
    <inertial>
      <origin
        xyz="0.2 0.295 0.03"
        rpy="0 0 0" />
      <mass
        value="2.1167" />
      <inertia
        ixx="0.0076561"
        ixy="-2.912E-15"
        ixz="-5.7644E-14"
        iyy="0.014045"
        iyz="1.412E-16"
        izz="0.0076561" />
    </inertial>
    <visual>
      <origin
        xyz="0 0 0"
        rpy="0 0 0" />
      <geometry>
        <mesh
          filename="package://pip/meshes/front_left_wheel.STL" />
      </geometry>
      <material
        name="">
        <color
          rgba="0.89804 0.89804 0.89804 1" />
      </material>
    </visual>
    <collision>
      <origin
        xyz="0 0 0"
        rpy="0 0 0" />
      <geometry>
        <mesh
          filename="package://pip/meshes/front_left_wheel.STL" />
      </geometry>
    </collision>
  </link>
  <joint
    name="front_left_joint"
    type="continuous">
    <origin
      xyz="0 0 0"
      rpy="0 0 0" />
    <parent
      link="base_link" />
    <child
      link="front_left_wheel" />
    <axis
      xyz="0 1 0" />
    <limit
      lower="0"
      upper="0"
      effort="1000"
      velocity="1000" />
    <dynamics
      damping="1"
      friction="1" />
  </joint>
  <link
    name="front_right_wheel">
    <inertial>
      <origin
        xyz="0.2 -0.295 0.03"
        rpy="0 0 0" />
      <mass
        value="2.1167" />
      <inertia
        ixx="0.0076561"
        ixy="1.9442E-16"
        ixz="-7.0137E-14"
        iyy="0.014045"
        iyz="-2.722E-15"
        izz="0.0076561" />
    </inertial>
    <visual>
      <origin
        xyz="0 0 0"
        rpy="0 0 0" />
      <geometry>
        <mesh
          filename="package://pip/meshes/front_right_wheel.STL" />
      </geometry>
      <material
        name="">
        <color
          rgba="0.89804 0.89804 0.89804 1" />
      </material>
    </visual>
    <collision>
      <origin
        xyz="0 0 0"
        rpy="0 0 0" />
      <geometry>
        <mesh
          filename="package://pip/meshes/front_right_wheel.STL" />
      </geometry>
    </collision>
  </link>
  <joint
    name="front_right_joint"
    type="continuous">
    <origin
      xyz="0 0 0"
      rpy="0 0 0" />
    <parent
      link="base_link" />
    <child
      link="front_right_wheel" />
    <axis
      xyz="0 -1 0" />
    <limit
      lower="0"
      upper="0"
      effort="1000"
      velocity="1000" />
    <dynamics
      damping="1"
      friction="1" />
  </joint>
  <link
    name="rear_left_wheel">
    <inertial>
      <origin
        xyz="-0.2 0.295 0.03"
        rpy="0 0 0" />
      <mass
        value="2.1167" />
      <inertia
        ixx="0.0076561"
        ixy="9.1094E-16"
        ixz="-6.7679E-14"
        iyy="0.014045"
        iyz="-2.1313E-15"
        izz="0.0076561" />
    </inertial>
    <visual>
      <origin
        xyz="0 0 0"
        rpy="0 0 0" />
      <geometry>
        <mesh
          filename="package://pip/meshes/rear_left_wheel.STL" />
      </geometry>
      <material
        name="">
        <color
          rgba="0.89804 0.89804 0.89804 1" />
      </material>
    </visual>
    <collision>
      <origin
        xyz="0 0 0"
        rpy="0 0 0" />
      <geometry>
        <mesh
          filename="package://pip/meshes/rear_left_wheel.STL" />
      </geometry>
    </collision>
  </link>
  <joint
    name="rear_left_joint"
    type="continuous">
    <origin
      xyz="0 0 0"
      rpy="0 0 0" />
    <parent
      link="base_link" />
    <child
      link="rear_left_wheel" />
    <axis
      xyz="0 1 0" />
    <limit
      lower="0"
      upper="0"
      effort="1000"
      velocity="1000" />
    <dynamics
      damping="1"
      friction="1" />
  </joint>
  <link
    name="rear_right_wheel">
    <inertial>
      <origin
        xyz="-0.2 -0.295 0.03"
        rpy="0 0 0" />
      <mass
        value="2.1167" />
      <inertia
        ixx="0.0076561"
        ixy="1.1546E-15"
        ixz="1.1842E-13"
        iyy="0.014045"
        iyz="1.7065E-15"
        izz="0.0076561" />
    </inertial>
    <visual>
      <origin
        xyz="0 0 0"
        rpy="0 0 0" />
      <geometry>
        <mesh
          filename="package://pip/meshes/rear_right_wheel.STL" />
      </geometry>
      <material
        name="">
        <color
          rgba="0.89804 0.89804 0.89804 1" />
      </material>
    </visual>
    <collision>
      <origin
        xyz="0 0 0"
        rpy="0 0 0" />
      <geometry>
        <mesh
          filename="package://pip/meshes/rear_right_wheel.STL" />
      </geometry>
    </collision>
  </link>
  <joint
    name="rear_right_joint"
    type="continuous">
    <origin
      xyz="0 0 0"
      rpy="0 0 0" />
    <parent
      link="base_link" />
    <child
      link="rear_right_wheel" />
    <axis
      xyz="0 -1 0" />
    <limit
      lower="0"
      upper="0"
      effort="1000"
      velocity="1000" />
    <dynamics
      damping="1"
      friction="1" />
  </joint>
</robot>